Workbook

Sheet README
A1: Employee Attrition Analysis - Excel Workbook
A2: Which factors drive employee turnover, and how can the organization reduce attrition and improve retention?
A4: NOTE: Raw_Data is a synthetic, IBM-HR-style sample (2,000 employees, exits Jan-2022 to Dec-2025) so the workbook runs end-to-end. Paste your own data into Raw_Data (same 14 columns) and everything recalculates.
A6: Parameters & assumptions (blue cells are editable inputs)
A7: Parameter | B7: Value | C7: Note
A8: As-of date (end of analysis window) | B8: 46022 | C8: Used to compute tenure for active employees.
A9: Default performance rating for blanks | B9: 3 | C9: Assumption: blank ratings treated as "Meets expectations" (median).
A10: Default job satisfaction for blanks | B10: 3 | C10: Assumption: blank scores treated as the median (3 on a 1-4 scale).
A11: Replacement cost as % of annual salary | B11: 0.5 | C11: ASSUMPTION (illustrative): recruiting + onboarding + lost productivity. Replace with HR/finance figure.
A12: Target attrition reduction | B12: 0.1 | C12: ASSUMPTION (illustrative): used for the savings estimate on the Analysis and Insights tabs.
A15: Workbook map
A16: Sheet | B16: Purpose | C16: Contents
A17: README | B17: Problem framing, assumptions, data-quality checks, column dictionary | C17: You are here
A18: Raw_Data | B18: Untouched source extract (never edited) | C18: 14 columns with deliberate inconsistencies: mixed-case labels, stray spaces, M/F codes, blanks
A19: Clean_Data | B19: Standardized, typed, enriched data (all formulas off Raw_Data) | C19: Standard headers, imputed blanks, Attrition_Flag, tenure, age/tenure/performance bands, exit year/quarter/month
A20: Analysis | B20: Formula-driven analysis tables (COUNTIFS / AVERAGEIFS on named ranges) | C20: KPIs, 10 demographic cuts, voluntary vs involuntary, exit reasons, yearly / quarterly / seasonal trends, role x department heatmap
A21: Pivots | B21: Slicer-style cross-tabs + how to add native PivotTables & slicers | C21: Dropdown filters drive role x age and role x gender attrition cross-tabs
A22: Dashboard | B22: One-page visual summary | C22: KPI cards, bar / pie / line charts, heatmap
A23: Insights | B23: Findings, recommendations, and demo script | C23: Findings are formula-built from the Analysis tab
A25: Metric definitions
A26: Segment attrition % | B26: Leavers in segment / employees ever in segment during the window (Jan-2022 to Dec-2025). Comparable across segments, but cumulative, so it is larger than an annual rate.
A27: Annual attrition rate | B27: Leavers in year / average headcount, where average headcount = (headcount at 1-Jan + headcount at 31-Dec) / 2. Used for all time-based views.
A28: Voluntary / Involuntary | B28: Taken from Attrition_Type. Leavers with a blank type are shown as "Unknown".
A29: Seasonality index | B29: Share of all exits that fall in a calendar month x 12. 1.0 = an average month; above 1.0 = a peak month.
A31: Data-quality checks (live)
A32: Check | B32: Result | C32: Treatment
A33: Total records | B33: =COUNTA(Raw_Data!A2:A2001) -> 2000 | C33: Rows loaded from the source file.
A34: Duplicate Employee IDs | B34: =SUMPRODUCT((COUNTIF(Raw_Data!A2:A2001,Raw_Data!A2:A2001)>1)*1) -> 0 | C34: Should be 0.
A35: Blank ages | B35: =COUNTBLANK(Raw_Data!D2:D2001) -> 6 | C35: Kept blank; reported as "Unknown" age band.
A36: Blank performance ratings | B36: =COUNTBLANK(Raw_Data!I2:I2001) -> 30 | C36: Imputed with the default rating above.
A37: Blank job-satisfaction scores | B37: =COUNTBLANK(Raw_Data!J2:J2001) -> 40 | C37: Imputed with the default score above.
A38: Leavers with blank attrition type | B38: =COUNTIFS(AttrFlag,1,AttrType,"Unknown") -> 17 | C38: Shown as "Unknown"; excluded from voluntary / involuntary split.
A39: Leavers with no exit reason | B39: =COUNTIF(ExitReason,"Not Recorded") -> 29 | C39: Shown as "Not Recorded" in reason tables.
A40: Exit date earlier than hire date | B40: =SUMPRODUCT((AttrFlag=1)*(TenureYrs<0)) -> 0 | C40: Should be 0.
A41: Unrecognised gender codes | B41: =COUNTIF(Gender,"Unknown") -> 0 | C41: Should be 0.
A43: Column dictionary (Clean_Data)
A44: Column | B44: Type | C44: Definition
A45: Employee_ID | B45: Text | C45: Unique employee identifier
A46: Hire_Date / Exit_Date | B46: Date | C46: Exit_Date blank = still active
A47: Age | B47: Number | C47: Age at exit (leavers) or at as-of date (active)
...

Sheet Raw_Data
A1: Emp ID | B1: Hire Date | C1: Exit Date | D1: Age | E1: gender | F1: Education Level | G1: department | H1: Job Role | I1: Perf Rating | J1: Job Satisfaction | K1: Monthly Income | L1: Attrition Type | M1: Exit Reason | N1: OverTime
A2: EMP0001 | B2: 40911 | D2: 43 | E2: M | F2: Diploma | G2: Operations | H2: Analyst | I2: 5 | J2: 3 | K2: 74500 | N2: Yes
A3: EMP0002 | B3: 40917 | C3: 45913 | D3: 39 | E3: Male | F3: Master's | G3: Sales | H3: Associate | I3: 2 | J3: 1 | K3: 42000 | L3: voluntary | M3: Relocation | N3: No
A4: EMP0003 | B4: 40922 | D4: 40 | E4: Female | F4: High School | G4: Operations | H4: Analyst | I4: 3 | J4: 1 | K4: 81500 | N4: No
A5: EMP0004 | B5: 40924 | D5: 39 | E5: Male | F5: High School | G5: Customer Support | H5: Specialist | I5: 4 | J5: 4 | K5: 129500 | N5: No
A6: EMP0005 | B6: 40934 | C6: 44706 | D6: 35 | E6: Female | F6: High School | G6: Customer Support | H6: Associate | I6: 4 | J6: 1 | K6: 60000 | L6: Voluntary | M6: Job Dissatisfaction | N6: No
A7: EMP0006 | B7: 40939 | D7: 48 | E7: Male | F7: bachelors | G7: Engineering | H7: Senior Analyst | I7: 3 | J7: 4 | K7: 125500 | N7: no
A8: EMP0007 | B8: 40939 | C8: 45777 | D8: 42 | E8: Male | F8: High School | G8: Sales | H8: Senior Analyst | I8: 4 | J8: 3 | K8: 123500 | L8: Voluntary | M8: Work-Life Balance | N8: Yes
A9: EMP0008 | B9: 40946 | D9: 42 | E9: Male | F9: Diploma | G9: Customer Support | H9: Senior Analyst | I9: 1 | J9: 2 | K9: 124500 | N9: Yes
A10: EMP0009 | B10: 40950 | D10: 35 | E10: female | F10: masters | G10: Operations | H10: Analyst | I10: 5 | J10: 2 | K10: 84000 | N10: Yes
A11: EMP0010 | B11: 40952 | D11: 44 | E11: Female | F11: Diploma | G11: Sales | H11: senior analyst | I11: 4 | J11: 4 | K11: 121500 | N11: no
A12: EMP0011 | B12: 40961 | D12: 37 | E12: Female | F12: Bachelor's | G12: Customer Support | H12: Associate | I12: 2 | J12: 3 | K12: 43500 | N12: No
A13: EMP0012 | B13: 40968 | C13: 44755 | D13: 44 | E13: Male | F13: Bachelors | G13: CUSTOMER SUPPORT | H13: associate | I13: 4 | J13: 4 | K13: 46000 | L13: Involuntary | M13: Policy Violation | N13: No
A14: EMP0013 | B14: 40970 | D14: 41 | E14: Male | F14: masters | G14: Operations | H14: Specialist | I14: 2 | J14: 4 | K14: 131500 | N14: No
A15: EMP0014 | B15: 40982 | D15: 45 | E15: M | F15: Bachelors | G15: Sales | H15: Associate | I15: 4 | J15: 3 | K15: 53500 | N15: no
A16: EMP0015 | B16: 40987 | D16: 41 | E16: Female | F16: Diploma | G16: Engineering | H16: Team Lead | I16: 4 | J16: 1 | K16: 190000 | N16: No
A17: EMP0016 | B17: 40994 | D17: 38 | E17: female | F17: masters | G17: Sales | H17: Team Lead | I17: 4 | J17: 4 | K17: 191500 | N17: Yes
A18: EMP0017 | B18: 40995 | D18: 36 | E18: Female | F18: Diploma | G18: Engineering | H18: Senior Analyst | I18: 4 | J18: 2 | K18: 126000 | N18: No
A19: EMP0018 | B19: 41016 | D19: 47 | E19: F | F19: masters | G19: Operations | H19: Analyst | I19: 5 | J19: 3 | K19: 82000 | N19: Yes
A20: EMP0019 | B20: 41018 | D20: 43 | E20: Male | F20: Diploma | G20: SALES | H20: Analyst | I20: 3 | J20: 2 | K20: 71500 | N20: No
A21: EMP0020 | B21: 41021 | D21: 37 | E21: Male | F21: High School | G21: Engineering | H21: Analyst | I21: 4 | J21: 4 | K21: 92500 | N21: Yes
A22: EMP0021 | B22: 41030 | D22: 44 | E22: Male | F22: Master's | G22: OPERATIONS | H22: Specialist | I22: 3 | J22: 1 | K22: 124000 | N22: no
A23: EMP0022 | B23: 41033 | C23: 45675 | D23: 47 | E23: Female | F23: Bachelor's | G23: Finance | H23: Manager | I23: 3 | J23: 3 | K23: 225000 | L23: Voluntary | M23: Job Dissatisfaction | N23: Yes
A24: EMP0023 | B24: 41036 | C24: 44655 | D24: 39 | E24: Male | F24: High School | G24: Operations | H24: Analyst | I24: 3 | J24: 2 | K24: 79500 | L24: Voluntary | M24: Job Dissatisfaction | N24: No
A25: EMP0024 | B25: 41038 | D25: 46 | E25: Female | F25: bachelors | G25: Sales | H25: Associate | I25: 3 | J25: 4 | K25: 50000 | N25: No
A26: EMP0025 | B26: 41039 | D26: 40 | E26: Male | F26: masters | G26: Sales | H26: Analyst | I26: 3 | J26: 2 | K26: 74000 | N26: No
A27: EMP0026 | B27: 41041 | D27: 35 | E27: Female | F27: Diploma | G27: Sales | H27: Manager | I27: 3 | J27: 4 | K27: 249000 | N27: No
A28: EMP0027 | B28: 41042 | D28: 36 | E28: Female | F28: Master's | G28: Engineering | H28: Associate | I28: 3 | J28: 4 | K28: 54000 | N28: Yes
A29: EMP0028 | B29: 41044 | C29: 44662 | D29: 37 | E29: Male | F29: Diploma | G29: Customer Support | H29: Associate | I29: 5 | J29: 1 | K29: 53000 | L29: VOLUNTARY | M29: Better Compensation | N29: No
A30: EMP0029 | B30: 41048 | C30: 45567 | D30: 42 | E30: M | F30: bachelors | G30: SALES | H30: Associate | I30: 3 | J30: 1 | K30: 42500 | L30: Voluntary | M30: Manager Issues | N30: no
A31: EMP0030 | B31: 41058 | D31: 47 | E31: Female | F31: Diploma | G31: Customer Support | H31: Senior Analyst | I31: 4 | K31: 121000 | N31: Yes
A32: EMP0031 | B32: 41058 | C32: 45730 | D32: 51 | E32: Male | F32: Bachelor's | G32: Sales | H32: Analyst | I32: 3 | J32: 3 | K32: 69000 | L32: Voluntary | M32: Personal Reasons | N32: Yes
A33: EMP0032 | B33: 41058 | D33: 43 | E33: Male | F33: Diploma | G33: Operations | H33: Team Lead | I33: 3 | J33: 1 | K33: 164000 | N33: No
A34: EMP0033 | B34: 41064 | D34: 43 | E34: female | F34: Diploma | G34: Customer Support | H34: Senior Analyst | I34: 3 | J34: 4 | K34: 135500 | N34: Yes
A35: EMP0034 | B35: 41066 | C35: 44622 | D35: 43 | E35: Male | F35: bachelors | G35: SALES | H35: Senior Analyst | I35: 3 | J35: 4 | K35: 124500 | L35: Voluntary | M35: Work-Life Balance | N35: Yes
A36: EMP0035 | B36: 41081 | D36: 44 | E36: female | F36: Master's | G36: Operations | H36: Specialist | I36: 4 | J36: 1 | K36: 110000 | N36: no
A37: EMP0036 | B37: 41088 | D37: 41 | E37: Male | F37: Bachelor's | G37: Engineering | H37: Analyst | I37: 3 | J37: 1 | K37: 73500 | N37: No
A38: EMP0037 | B38: 41095 | D38: 43 | E38: Female | F38: Bachelors | G38: Human Resources | H38: Analyst | I38: 4 | J38: 1 | K38: 90500 | N38: NO
A39: EMP0038 | B39: 41099 | C39: 45541 | D39: 49 | E39: M | F39: Bachelor's | G39: Customer Support | H39: Associate | I39: 2 | J39: 3 | K39: 50000 | L39: Voluntary | M39: Career Growth | N39: No
A40: EMP0039 | B40: 41099 | C40: 45550 | D40: 41 | E40: M | F40: bachelors | G40: Operations | H40: Analyst | I40: 3 | J40: 2 | K40: 72000 | L40: Voluntary | M40: Work-Life Balance | N40: No
...

Sheet Clean_Data
A1: Employee_ID | B1: Hire_Date | C1: Exit_Date | D1: Age | E1: Gender | F1: Education | G1: Department | H1: Job_Role | I1: Performance_Rating | J1: Job_Satisfaction | K1: Monthly_Income | L1: Overtime | M1: Attrition_Flag | N1: Attrition_Type | O1: Exit_Reason | P1: Tenure_Years | Q1: Age_Band | R1: Tenure_Band | S1: Perf_Group | T1: Exit_Year | U1: Exit_Quarter | V1: Exit_Month
A2: =TRIM(Raw_Data!A2) -> EMP0001 | B2: =Raw_Data!B2 -> 40911 | C2: =IF(Raw_Data!C2="","",Raw_Data!C2) | D2: =IF(Raw_Data!D2="","",Raw_Data!D2) -> 43 | E2: =IF(UPPER(LEFT(TRIM(Raw_Data!E2),1))="M","Male",IF(UPPER(LEFT(TRIM(Raw_Data!E2),1))="F","Female","Unknown")) -> Male | F2: =PROPER(TRIM(SUBSTITUTE(Raw_Data!F2,"'",""))) -> Diploma | G2: =PROPER(TRIM(Raw_Data!G2)) -> Operations | H2: =PROPER(TRIM(Raw_Data!H2)) -> Analyst | I2: =IF(Raw_Data!I2="",DefaultPerf,Raw_Data!I2) -> 5 | J2: =IF(Raw_Data!J2="",DefaultSat,Raw_Data!J2) -> 3 | K2: =Raw_Data!K2 -> 74500 | L2: =PROPER(TRIM(Raw_Data!N2)) -> Yes | M2: =IF(C2="",0,1) -> 0 | N2: =IF(M2=0,"Active",IF(TRIM(Raw_Data!L2)="","Unknown",PROPER(TRIM(Raw_Data!L2)))) -> Active | O2: =IF(M2=0,"",IF(TRIM(Raw_Data!M2)="","Not Recorded",TRIM(Raw_Data!M2))) | P2: =ROUND((IF(C2="",AsOfDate,C2)-B2)/365.25,2) -> 13.99 | Q2: =IF(D2="","Unknown",IF(D2<25,"Under 25",IF(D2<35,"25-34",IF(D2<45,"35-44",IF(D2<55,"45-54","55+"))))) -> 35-44 | R2: =IF(P2<1,"0-1 yrs",IF(P2<3,"1-3 yrs",IF(P2<5,"3-5 yrs",IF(P2<10,"5-10 yrs","10+ yrs")))) -> 10+ yrs | S2: =IF(I2>=4,"High",IF(I2=3,"Medium","Low")) -> High | T2: =IF(M2=1,YEAR(C2),"") | U2: =IF(M2=1,YEAR(C2)&"-Q"&ROUNDUP(MONTH(C2)/3,0),"") | V2: =IF(M2=1,MONTH(C2),"")
A3: =TRIM(Raw_Data!A3) -> EMP0002 | B3: =Raw_Data!B3 -> 40917 | C3: =IF(Raw_Data!C3="","",Raw_Data!C3) -> 45913 | D3: =IF(Raw_Data!D3="","",Raw_Data!D3) -> 39 | E3: =IF(UPPER(LEFT(TRIM(Raw_Data!E3),1))="M","Male",IF(UPPER(LEFT(TRIM(Raw_Data!E3),1))="F","Female","Unknown")) -> Male | F3: =PROPER(TRIM(SUBSTITUTE(Raw_Data!F3,"'",""))) -> Masters | G3: =PROPER(TRIM(Raw_Data!G3)) -> Sales | H3: =PROPER(TRIM(Raw_Data!H3)) -> Associate | I3: =IF(Raw_Data!I3="",DefaultPerf,Raw_Data!I3) -> 2 | J3: =IF(Raw_Data!J3="",DefaultSat,Raw_Data!J3) -> 1 | K3: =Raw_Data!K3 -> 42000 | L3: =PROPER(TRIM(Raw_Data!N3)) -> No | M3: =IF(C3="",0,1) -> 1 | N3: =IF(M3=0,"Active",IF(TRIM(Raw_Data!L3)="","Unknown",PROPER(TRIM(Raw_Data!L3)))) -> Voluntary | O3: =IF(M3=0,"",IF(TRIM(Raw_Data!M3)="","Not Recorded",TRIM(Raw_Data!M3))) -> Relocation | P3: =ROUND((IF(C3="",AsOfDate,C3)-B3)/365.25,2) -> 13.68 | Q3: =IF(D3="","Unknown",IF(D3<25,"Under 25",IF(D3<35,"25-34",IF(D3<45,"35-44",IF(D3<55,"45-54","55+"))))) -> 35-44 | R3: =IF(P3<1,"0-1 yrs",IF(P3<3,"1-3 yrs",IF(P3<5,"3-5 yrs",IF(P3<10,"5-10 yrs","10+ yrs")))) -> 10+ yrs | S3: =IF(I3>=4,"High",IF(I3=3,"Medium","Low")) -> Low | T3: =IF(M3=1,YEAR(C3),"") -> 2025 | U3: =IF(M3=1,YEAR(C3)&"-Q"&ROUNDUP(MONTH(C3)/3,0),"") -> 2025-Q3 | V3: =IF(M3=1,MONTH(C3),"") -> 9
A4: =TRIM(Raw_Data!A4) -> EMP0003 | B4: =Raw_Data!B4 -> 40922 | C4: =IF(Raw_Data!C4="","",Raw_Data!C4) | D4: =IF(Raw_Data!D4="","",Raw_Data!D4) -> 40 | E4: =IF(UPPER(LEFT(TRIM(Raw_Data!E4),1))="M","Male",IF(UPPER(LEFT(TRIM(Raw_Data!E4),1))="F","Female","Unknown")) -> Female | F4: =PROPER(TRIM(SUBSTITUTE(Raw_Data!F4,"'",""))) -> High School | G4: =PROPER(TRIM(Raw_Data!G4)) -> Operations | H4: =PROPER(TRIM(Raw_Data!H4)) -> Analyst | I4: =IF(Raw_Data!I4="",DefaultPerf,Raw_Data!I4) -> 3 | J4: =IF(Raw_Data!J4="",DefaultSat,Raw_Data!J4) -> 1 | K4: =Raw_Data!K4 -> 81500 | L4: =PROPER(TRIM(Raw_Data!N4)) -> No | M4: =IF(C4="",0,1) -> 0 | N4: =IF(M4=0,"Active",IF(TRIM(Raw_Data!L4)="","Unknown",PROPER(TRIM(Raw_Data!L4)))) -> Active | O4: =IF(M4=0,"",IF(TRIM(Raw_Data!M4)="","Not Recorded",TRIM(Raw_Data!M4))) | P4: =ROUND((IF(C4="",AsOfDate,C4)-B4)/365.25,2) -> 13.96 | Q4: =IF(D4="","Unknown",IF(D4<25,"Under 25",IF(D4<35,"25-34",IF(D4<45,"35-44",IF(D4<55,"45-54","55+"))))) -> 35-44 | R4: =IF(P4<1,"0-1 yrs",IF(P4<3,"1-3 yrs",IF(P4<5,"3-5 yrs",IF(P4<10,"5-10 yrs","10+ yrs")))) -> 10+ yrs | S4: =IF(I4>=4,"High",IF(I4=3,"Medium","Low")) -> Medium | T4: =IF(M4=1,YEAR(C4),"") | U4: =IF(M4=1,YEAR(C4)&"-Q"&ROUNDUP(MONTH(C4)/3,0),"") | V4: =IF(M4=1,MONTH(C4),"")
A5: =TRIM(Raw_Data!A5) -> EMP0004 | B5: =Raw_Data!B5 -> 40924 | C5: =IF(Raw_Data!C5="","",Raw_Data!C5) | D5: =IF(Raw_Data!D5="","",Raw_Data!D5) -> 39 | E5: =IF(UPPER(LEFT(TRIM(Raw_Data!E5),1))="M","Male",IF(UPPER(LEFT(TRIM(Raw_Data!E5),1))="F","Female","Unknown")) -> Male | F5: =PROPER(TRIM(SUBSTITUTE(Raw_Data!F5,"'",""))) -> High School | G5: =PROPER(TRIM(Raw_Data!G5)) -> Customer Support | H5: =PROPER(TRIM(Raw_Data!H5)) -> Specialist | I5: =IF(Raw_Data!I5="",DefaultPerf,Raw_Data!I5) -> 4 | J5: =IF(Raw_Data!J5="",DefaultSat,Raw_Data!J5) -> 4 | K5: =Raw_Data!K5 -> 129500 | L5: =PROPER(TRIM(Raw_Data!N5)) -> No | M5: =IF(C5="",0,1) -> 0 | N5: =IF(M5=0,"Active",IF(TRIM(Raw_Data!L5)="","Unknown",PROPER(TRIM(Raw_Data!L5)))) -> Active | O5: =IF(M5=0,"",IF(TRIM(Raw_Data!M5)="","Not Recorded",TRIM(Raw_Data!M5))) | P5: =ROUND((IF(C5="",AsOfDate,C5)-B5)/365.25,2) -> 13.96 | Q5: =IF(D5="","Unknown",IF(D5<25,"Under 25",IF(D5<35,"25-34",IF(D5<45,"35-44",IF(D5<55,"45-54","55+"))))) -> 35-44 | R5: =IF(P5<1,"0-1 yrs",IF(P5<3,"1-3 yrs",IF(P5<5,"3-5 yrs",IF(P5<10,"5-10 yrs","10+ yrs")))) -> 10+ yrs | S5: =IF(I5>=4,"High",IF(I5=3,"Medium","Low")) -> High | T5: =IF(M5=1,YEAR(C5),"") | U5: =IF(M5=1,YEAR(C5)&"-Q"&ROUNDUP(MONTH(C5)/3,0),"") | V5: =IF(M5=1,MONTH(C5),"")
A6: =TRIM(Raw_Data!A6) -> EMP0005 | B6: =Raw_Data!B6 -> 40934 | C6: =IF(Raw_Data!C6="","",Raw_Data!C6) -> 44706 | D6: =IF(Raw_Data!D6="","",Raw_Data!D6) -> 35 | E6: =IF(UPPER(LEFT(TRIM(Raw_Data!E6),1))="M","Male",IF(UPPER(LEFT(TRIM(Raw_Data!E6),1))="F","Female","Unknown")) -> Female | F6: =PROPER(TRIM(SUBSTITUTE(Raw_Data!F6,"'",""))) -> High School | G6: =PROPER(TRIM(Raw_Data!G6)) -> Customer Support | H6: =PROPER(TRIM(Raw_Data!H6)) -> Associate | I6: =IF(Raw_Data!I6="",DefaultPerf,Raw_Data!I6) -> 4 | J6: =IF(Raw_Data!J6="",DefaultSat,Raw_Data!J6) -> 1 | K6: =Raw_Data!K6 -> 60000 | L6: =PROPER(TRIM(Raw_Data!N6)) -> No | M6: =IF(C6="",0,1) -> 1 | N6: =IF(M6=0,"Active",IF(TRIM(Raw_Data!L6)="","Unknown",PROPER(TRIM(Raw_Data!L6)))) -> Voluntary | O6: =IF(M6=0,"",IF(TRIM(Raw_Data!M6)="","Not Recorded",TRIM(Raw_Data!M6))) -> Job Dissatisfaction | P6: =ROUND((IF(C6="",AsOfDate,C6)-B6)/365.25,2) -> 10.33 | Q6: =IF(D6="","Unknown",IF(D6<25,"Under 25",IF(D6<35,"25-34",IF(D6<45,"35-44",IF(D6<55,"45-54","55+"))))) -> 35-44 | R6: =IF(P6<1,"0-1 yrs",IF(P6<3,"1-3 yrs",IF(P6<5,"3-5 yrs",IF(P6<10,"5-10 yrs","10+ yrs")))) -> 10+ yrs | S6: =IF(I6>=4,"High",IF(I6=3,"Medium","Low")) -> High | T6: =IF(M6=1,YEAR(C6),"") -> 2022 | U6: =IF(M6=1,YEAR(C6)&"-Q"&ROUNDUP(MONTH(C6)/3,0),"") -> 2022-Q2 | V6: =IF(M6=1,MONTH(C6),"") -> 5
A7: =TRIM(Raw_Data!A7) -> EMP0006 | B7: =Raw_Data!B7 -> 40939 | C7: =IF(Raw_Data!C7="","",Raw_Data!C7) | D7: =IF(Raw_Data!D7="","",Raw_Data!D7) -> 48 | E7: =IF(UPPER(LEFT(TRIM(Raw_Data!E7),1))="M","Male",IF(UPPER(LEFT(TRIM(Raw_Data!E7),1))="F","Female","Unknown")) -> Male | F7: =PROPER(TRIM(SUBSTITUTE(Raw_Data!F7,"'",""))) -> Bachelors | G7: =PROPER(TRIM(Raw_Data!G7)) -> Engineering | H7: =PROPER(TRIM(Raw_Data!H7)) -> Senior Analyst | I7: =IF(Raw_Data!I7="",DefaultPerf,Raw_Data!I7) -> 3 | J7: =IF(Raw_Data!J7="",DefaultSat,Raw_Data!J7) -> 4 | K7: =Raw_Data!K7 -> 125500 | L7: =PROPER(TRIM(Raw_Data!N7)) -> No | M7: =IF(C7="",0,1) -> 0 | N7: =IF(M7=0,"Active",IF(TRIM(Raw_Data!L7)="","Unknown",PROPER(TRIM(Raw_Data!L7)))) -> Active | O7: =IF(M7=0,"",IF(TRIM(Raw_Data!M7)="","Not Recorded",TRIM(Raw_Data!M7))) | P7: =ROUND((IF(C7="",AsOfDate,C7)-B7)/365.25,2) -> 13.92 | Q7: =IF(D7="","Unknown",IF(D7<25,"Under 25",IF(D7<35,"25-34",IF(D7<45,"35-44",IF(D7<55,"45-54","55+"))))) -> 45-54 | R7: =IF(P7<1,"0-1 yrs",IF(P7<3,"1-3 yrs",IF(P7<5,"3-5 yrs",IF(P7<10,"5-10 yrs","10+ yrs")))) -> 10+ yrs | S7: =IF(I7>=4,"High",IF(I7=3,"Medium","Low")) -> Medium | T7: =IF(M7=1,YEAR(C7),"") | U7: =IF(M7=1,YEAR(C7)&"-Q"&ROUNDUP(MONTH(C7)/3,0),"") | V7: =IF(M7=1,MONTH(C7),"")
A8: =TRIM(Raw_Data!A8) -> EMP0007 | B8: =Raw_Data!B8 -> 40939 | C8: =IF(Raw_Data!C8="","",Raw_Data!C8) -> 45777 | D8: =IF(Raw_Data!D8="","",Raw_Data!D8) -> 42 | E8: =IF(UPPER(LEFT(TRIM(Raw_Data!E8),1))="M","Male",IF(UPPER(LEFT(TRIM(Raw_Data!E8),1))="F","Female","Unknown")) -> Male | F8: =PROPER(TRIM(SUBSTITUTE(Raw_Data!F8,"'",""))) -> High School | G8: =PROPER(TRIM(Raw_Data!G8)) -> Sales | H8: =PROPER(TRIM(Raw_Data!H8)) -> Senior Analyst | I8: =IF(Raw_Data!I8="",DefaultPerf,Raw_Data!I8) -> 4 | J8: =IF(Raw_Data!J8="",DefaultSat,Raw_Data!J8) -> 3 | K8: =Raw_Data!K8 -> 123500 | L8: =PROPER(TRIM(Raw_Data!N8)) -> Yes | M8: =IF(C8="",0,1) -> 1 | N8: =IF(M8=0,"Active",IF(TRIM(Raw_Data!L8)="","Unknown",PROPER(TRIM(Raw_Data!L8)))) -> Voluntary | O8: =IF(M8=0,"",IF(TRIM(Raw_Data!M8)="","Not Recorded",TRIM(Raw_Data!M8))) -> Work-Life Balance | P8: =ROUND((IF(C8="",AsOfDate,C8)-B8)/365.25,2) -> 13.25 | Q8: =IF(D8="","Unknown",IF(D8<25,"Under 25",IF(D8<35,"25-34",IF(D8<45,"35-44",IF(D8<55,"45-54","55+"))))) -> 35-44 | R8: =IF(P8<1,"0-1 yrs",IF(P8<3,"1-3 yrs",IF(P8<5,"3-5 yrs",IF(P8<10,"5-10 yrs","10+ yrs")))) -> 10+ yrs | S8: =IF(I8>=4,"High",IF(I8=3,"Medium","Low")) -> High | T8: =IF(M8=1,YEAR(C8),"") -> 2025 | U8: =IF(M8=1,YEAR(C8)&"-Q"&ROUNDUP(MONTH(C8)/3,0),"") -> 2025-Q2 | V8: =IF(M8=1,MONTH(C8),"") -> 4
A9: =TRIM(Raw_Data!A9) -> EMP0008 | B9: =Raw_Data!B9 -> 40946 | C9: =IF(Raw_Data!C9="","",Raw_Data!C9) | D9: =IF(Raw_Data!D9="","",Raw_Data!D9) -> 42 | E9: =IF(UPPER(LEFT(TRIM(Raw_Data!E9),1))="M","Male",IF(UPPER(LEFT(TRIM(Raw_Data!E9),1))="F","Female","Unknown")) -> Male | F9: =PROPER(TRIM(SUBSTITUTE(Raw_Data!F9,"'",""))) -> Diploma | G9: =PROPER(TRIM(Raw_Data!G9)) -> Customer Support | H9: =PROPER(TRIM(Raw_Data!H9)) -> Senior Analyst | I9: =IF(Raw_Data!I9="",DefaultPerf,Raw_Data!I9) -> 1 | J9: =IF(Raw_Data!J9="",DefaultSat,Raw_Data!J9) -> 2 | K9: =Raw_Data!K9 -> 124500 | L9: =PROPER(TRIM(Raw_Data!N9)) -> Yes | M9: =IF(C9="",0,1) -> 0 | N9: =IF(M9=0,"Active",IF(TRIM(Raw_Data!L9)="","Unknown",PROPER(TRIM(Raw_Data!L9)))) -> Active | O9: =IF(M9=0,"",IF(TRIM(Raw_Data!M9)="","Not Recorded",TRIM(Raw_Data!M9))) | P9: =ROUND((IF(C9="",AsOfDate,C9)-B9)/365.25,2) -> 13.9 | Q9: =IF(D9="","Unknown",IF(D9<25,"Under 25",IF(D9<35,"25-34",IF(D9<45,"35-44",IF(D9<55,"45-54","55+"))))) -> 35-44 | R9: =IF(P9<1,"0-1 yrs",IF(P9<3,"1-3 yrs",IF(P9<5,"3-5 yrs",IF(P9<10,"5-10 yrs","10+ yrs")))) -> 10+ yrs | S9: =IF(I9>=4,"High",IF(I9=3,"Medium","Low")) -> Low | T9: =IF(M9=1,YEAR(C9),"") | U9: =IF(M9=1,YEAR(C9)&"-Q"&ROUNDUP(MONTH(C9)/3,0),"") | V9: =IF(M9=1,MONTH(C9),"")
A10: =TRIM(Raw_Data!A10) -> EMP0009 | B10: =Raw_Data!B10 -> 40950 | C10: =IF(Raw_Data!C10="","",Raw_Data!C10) | D10: =IF(Raw_Data!D10="","",Raw_Data!D10) -> 35 | E10: =IF(UPPER(LEFT(TRIM(Raw_Data!E10),1))="M","Male",IF(UPPER(LEFT(TRIM(Raw_Data!E10),1))="F","Female","Unknown")) -> Female | F10: =PROPER(TRIM(SUBSTITUTE(Raw_Data!F10,"'",""))) -> Masters | G10: =PROPER(TRIM(Raw_Data!G10)) -> Operations | H10: =PROPER(TRIM(Raw_Data!H10)) -> Analyst | I10: =IF(Raw_Data!I10="",DefaultPerf,Raw_Data!I10) -> 5 | J10: =IF(Raw_Data!J10="",DefaultSat,Raw_Data!J10) -> 2 | K10: =Raw_Data!K10 -> 84000 | L10: =PROPER(TRIM(Raw_Data!N10)) -> Yes | M10: =IF(C10="",0,1) -> 0 | N10: =IF(M10=0,"Active",IF(TRIM(Raw_Data!L10)="","Unknown",PROPER(TRIM(Raw_Data!L10)))) -> Active | O10: =IF(M10=0,"",IF(TRIM(Raw_Data!M10)="","Not Recorded",TRIM(Raw_Data!M10))) | P10: =ROUND((IF(C10="",AsOfDate,C10)-B10)/365.25,2) -> 13.89 | Q10: =IF(D10="","Unknown",IF(D10<25,"Under 25",IF(D10<35,"25-34",IF(D10<45,"35-44",IF(D10<55,"45-54","55+"))))) -> 35-44 | R10: =IF(P10<1,"0-1 yrs",IF(P10<3,"1-3 yrs",IF(P10<5,"3-5 yrs",IF(P10<10,"5-10 yrs","10+ yrs")))) -> 10+ yrs | S10: =IF(I10>=4,"High",IF(I10=3,"Medium","Low")) -> High | T10: =IF(M10=1,YEAR(C10),"") | U10: =IF(M10=1,YEAR(C10)&"-Q"&ROUNDUP(MONTH(C10)/3,0),"") | V10: =IF(M10=1,MONTH(C10),"")
A11: =TRIM(Raw_Data!A11) -> EMP0010 | B11: =Raw_Data!B11 -> 40952 | C11: =IF(Raw_Data!C11="","",Raw_Data!C11) | D11: =IF(Raw_Data!D11="","",Raw_Data!D11) -> 44 | E11: =IF(UPPER(LEFT(TRIM(Raw_Data!E11),1))="M","Male",IF(UPPER(LEFT(TRIM(Raw_Data!E11),1))="F","Female","Unknown")) -> Female | F11: =PROPER(TRIM(SUBSTITUTE(Raw_Data!F11,"'",""))) -> Diploma | G11: =PROPER(TRIM(Raw_Data!G11)) -> Sales | H11: =PROPER(TRIM(Raw_Data!H11)) -> Senior Analyst | I11: =IF(Raw_Data!I11="",DefaultPerf,Raw_Data!I11) -> 4 | J11: =IF(Raw_Data!J11="",DefaultSat,Raw_Data!J11) -> 4 | K11: =Raw_Data!K11 -> 121500 | L11: =PROPER(TRIM(Raw_Data!N11)) -> No | M11: =IF(C11="",0,1) -> 0 | N11: =IF(M11=0,"Active",IF(TRIM(Raw_Data!L11)="","Unknown",PROPER(TRIM(Raw_Data!L11)))) -> Active | O11: =IF(M11=0,"",IF(TRIM(Raw_Data!M11)="","Not Recorded",TRIM(Raw_Data!M11))) | P11: =ROUND((IF(C11="",AsOfDate,C11)-B11)/365.25,2) -> 13.88 | Q11: =IF(D11="","Unknown",IF(D11<25,"Under 25",IF(D11<35,"25-34",IF(D11<45,"35-44",IF(D11<55,"45-54","55+"))))) -> 35-44 | R11: =IF(P11<1,"0-1 yrs",IF(P11<3,"1-3 yrs",IF(P11<5,"3-5 yrs",IF(P11<10,"5-10 yrs","10+ yrs")))) -> 10+ yrs | S11: =IF(I11>=4,"High",IF(I11=3,"Medium","Low")) -> High | T11: =IF(M11=1,YEAR(C11),"") | U11: =IF(M11=1,YEAR(C11)&"-Q"&ROUNDUP(MONTH(C11)/3,0),"") | V11: =IF(M11=1,MONTH(C11),"")
A12: =TRIM(Raw_Data!A12) -> EMP0011 | B12: =Raw_Data!B12 -> 40961 | C12: =IF(Raw_Data!C12="","",Raw_Data!C12) | D12: =IF(Raw_Data!D12="","",Raw_Data!D12) -> 37 | E12: =IF(UPPER(LEFT(TRIM(Raw_Data!E12),1))="M","Male",IF(UPPER(LEFT(TRIM(Raw_Data!E12),1))="F","Female","Unknown")) -> Female | F12: =PROPER(TRIM(SUBSTITUTE(Raw_Data!F12,"'",""))) -> Bachelors | G12: =PROPER(TRIM(Raw_Data!G12)) -> Customer Support | H12: =PROPER(TRIM(Raw_Data!H12)) -> Associate | I12: =IF(Raw_Data!I12="",DefaultPerf,Raw_Data!I12) -> 2 | J12: =IF(Raw_Data!J12="",DefaultSat,Raw_Data!J12) -> 3 | K12: =Raw_Data!K12 -> 43500 | L12: =PROPER(TRIM(Raw_Data!N12)) -> No | M12: =IF(C12="",0,1) -> 0 | N12: =IF(M12=0,"Active",IF(TRIM(Raw_Data!L12)="","Unknown",PROPER(TRIM(Raw_Data!L12)))) -> Active | O12: =IF(M12=0,"",IF(TRIM(Raw_Data!M12)="","Not Recorded",TRIM(Raw_Data!M12))) | P12: =ROUND((IF(C12="",AsOfDate,C12)-B12)/365.25,2) -> 13.86 | Q12: =IF(D12="","Unknown",IF(D12<25,"Under 25",IF(D12<35,"25-34",IF(D12<45,"35-44",IF(D12<55,"45-54","55+"))))) -> 35-44 | R12: =IF(P12<1,"0-1 yrs",IF(P12<3,"1-3 yrs",IF(P12<5,"3-5 yrs",IF(P12<10,"5-10 yrs","10+ yrs")))) -> 10+ yrs | S12: =IF(I12>=4,"High",IF(I12=3,"Medium","Low")) -> Low | T12: =IF(M12=1,YEAR(C12),"") | U12: =IF(M12=1,YEAR(C12)&"-Q"&ROUNDUP(MONTH(C12)/3,0),"") | V12: =IF(M12=1,MONTH(C12),"")
A13: =TRIM(Raw_Data!A13) -> EMP0012 | B13: =Raw_Data!B13 -> 40968 | C13: =IF(Raw_Data!C13="","",Raw_Data!C13) -> 44755 | D13: =IF(Raw_Data!D13="","",Raw_Data!D13) -> 44 | E13: =IF(UPPER(LEFT(TRIM(Raw_Data!E13),1))="M","Male",IF(UPPER(LEFT(TRIM(Raw_Data!E13),1))="F","Female","Unknown")) -> Male | F13: =PROPER(TRIM(SUBSTITUTE(Raw_Data!F13,"'",""))) -> Bachelors | G13: =PROPER(TRIM(Raw_Data!G13)) -> Customer Support | H13: =PROPER(TRIM(Raw_Data!H13)) -> Associate | I13: =IF(Raw_Data!I13="",DefaultPerf,Raw_Data!I13) -> 4 | J13: =IF(Raw_Data!J13="",DefaultSat,Raw_Data!J13) -> 4 | K13: =Raw_Data!K13 -> 46000 | L13: =PROPER(TRIM(Raw_Data!N13)) -> No | M13: =IF(C13="",0,1) -> 1 | N13: =IF(M13=0,"Active",IF(TRIM(Raw_Data!L13)="","Unknown",PROPER(TRIM(Raw_Data!L13)))) -> Involuntary | O13: =IF(M13=0,"",IF(TRIM(Raw_Data!M13)="","Not Recorded",TRIM(Raw_Data!M13))) -> Policy Violation | P13: =ROUND((IF(C13="",AsOfDate,C13)-B13)/365.25,2) -> 10.37 | Q13: =IF(D13="","Unknown",IF(D13<25,"Under 25",IF(D13<35,"25-34",IF(D13<45,"35-44",IF(D13<55,"45-54","55+"))))) -> 35-44 | R13: =IF(P13<1,"0-1 yrs",IF(P13<3,"1-3 yrs",IF(P13<5,"3-5 yrs",IF(P13<10,"5-10 yrs","10+ yrs")))) -> 10+ yrs | S13: =IF(I13>=4,"High",IF(I13=3,"Medium","Low")) -> High | T13: =IF(M13=1,YEAR(C13),"") -> 2022 | U13: =IF(M13=1,YEAR(C13)&"-Q"&ROUNDUP(MONTH(C13)/3,0),"") -> 2022-Q3 | V13: =IF(M13=1,MONTH(C13),"") -> 7
... A2001: =TRIM(Raw_Data!A2001) -> EMP2000 | B2001: =Raw_Data!B2001 -> 45961 | C2001: =IF(Raw_Data!C2001="","",Raw_Data!C2001) | D2001: =IF(Raw_Data!D2001="","",Raw_Data!D2001) -> 23 | E2001: =IF(UPPER(LEFT(TRIM(Raw_Data!E2001),1))="M","Male",IF(UPPER(LEFT(TRIM(Raw_Data!E2001),1))="F","Female","Unknown")) -> Male | F2001: =PROPER(TRIM(SUBSTITUTE(Raw_Data!F2001,"'",""))) -> Masters | G2001: =PROPER(TRIM(Raw_Data!G2001)) -> Sales | H2001: =PROPER(TRIM(Raw_Data!H2001)) -> Associate | I2001: =IF(Raw_Data!I2001="",DefaultPerf,Raw_Data!I2001) -> 4 | J2001: =IF(Raw_Data!J2001="",DefaultSat,Raw_Data!J2001) -> 3 | K2001: =Raw_Data!K2001 -> 30000 | L2001: =PROPER(TRIM(Raw_Data!N2001)) -> No | M2001: =IF(C2001="",0,1) -> 0 | N2001: =IF(M2001=0,"Active",IF(TRIM(Raw_Data!L2001)="","Unknown",PROPER(TRIM(Raw_Data!L2001)))) -> Active | O2001: =IF(M2001=0,"",IF(TRIM(Raw_Data!M2001)="","Not Recorded",TRIM(Raw_Data!M2001))) | P2001: =ROUND((IF(C2001="",AsOfDate,C2001)-B2001)/365.25,2) -> 0.17 | Q2001: =IF(D2001="","Unknown",IF(D2001<25,"Under 25",IF(D2001<35,"25-34",IF(D2001<45,"35-44",IF(D2001<55,"45-54","55+"))))) -> Under 25 | R2001: =IF(P2001<1,"0-1 yrs",IF(P2001<3,"1-3 yrs",IF(P2001<5,"3-5 yrs",IF(P2001<10,"5-10 yrs","10+ yrs")))) -> 0-1 yrs | S2001: =IF(I2001>=4,"High",IF(I2001=3,"Medium","Low")) -> High | T2001: =IF(M2001=1,YEAR(C2001),"") | U2001: =IF(M2001=1,YEAR(C2001)&"-Q"&ROUNDUP(MONTH(C2001)/3,0),"") | V2001: =IF(M2001=1,MONTH(C2001),"")

Sheet Analysis
A1: Attrition Analysis (all cells are formulas on Clean_Data named ranges)
A3: 1. Headline KPIs
A4: Metric | B4: Value
A5: Total employees in dataset | B5: =COUNTA(EmpID) -> 2000
A6: Active employees (31-Dec-2025) | B6: =COUNTIFS(AttrFlag,0) -> 1265
A7: Leavers (2022-2025) | B7: =COUNTIFS(AttrFlag,1) -> 735
A8: Cumulative attrition % (leavers / employees) | B8: =IFERROR(B7/B5,0) -> 0.3675
A9: Voluntary leavers | B9: =COUNTIFS(AttrType,"Voluntary") -> 557
A10: Involuntary leavers | B10: =COUNTIFS(AttrType,"Involuntary") -> 161
A11: Voluntary share of leavers | B11: =IFERROR(B9/B7,0) -> 0.75782313
A12: Average annual attrition rate | B12: =AVERAGE(G150:G153) -> 0.14617617
A13: Avg tenure of leavers (yrs) | B13: =AVERAGEIFS(TenureYrs,AttrFlag,1) -> 3.9238231
A14: Avg tenure of active employees (yrs) | B14: =AVERAGEIFS(TenureYrs,AttrFlag,0) -> 6.1839526
A15: Avg monthly income - leavers (INR) | B15: =AVERAGEIFS(Income,AttrFlag,1) -> 81664.626
A16: Avg monthly income - active (INR) | B16: =AVERAGEIFS(Income,AttrFlag,0) -> 92596.047
A17: Est. replacement cost, 2022-2025 (INR) | B17: =SUMIFS(Income,AttrFlag,1)*12*ReplCostPct -> 360141000 | C17: Uses ReplCostPct assumption (README)
A18: Est. average annual replacement cost (INR) | B18: =B17/ROWS(G150:G153) -> 90035250
A19: Est. annual saving at target reduction (INR) | B19: =B17*TargetReduction -> 36014100 | C19: Uses TargetReduction assumption (README)
A22: 2. Attrition by Department
A23: Segment | B23: Headcount | C23: Leavers | D23: Attrition % | E23: Voluntary | F23: Involuntary
A24: Sales | B24: =COUNTIFS(Dept,$A24) -> 445 | C24: =COUNTIFS(Dept,$A24,AttrFlag,1) -> 181 | D24: =IFERROR(C24/B24,0) -> 0.40674157 | E24: =COUNTIFS(Dept,$A24,AttrType,"Voluntary") -> 135 | F24: =COUNTIFS(Dept,$A24,AttrType,"Involuntary") -> 42
A25: Engineering | B25: =COUNTIFS(Dept,$A25) -> 559 | C25: =COUNTIFS(Dept,$A25,AttrFlag,1) -> 206 | D25: =IFERROR(C25/B25,0) -> 0.36851521 | E25: =COUNTIFS(Dept,$A25,AttrType,"Voluntary") -> 153 | F25: =COUNTIFS(Dept,$A25,AttrType,"Involuntary") -> 46
A26: Customer Support | B26: =COUNTIFS(Dept,$A26) -> 359 | C26: =COUNTIFS(Dept,$A26,AttrFlag,1) -> 155 | D26: =IFERROR(C26/B26,0) -> 0.43175487 | E26: =COUNTIFS(Dept,$A26,AttrType,"Voluntary") -> 119 | F26: =COUNTIFS(Dept,$A26,AttrType,"Involuntary") -> 33
A27: Finance | B27: =COUNTIFS(Dept,$A27) -> 165 | C27: =COUNTIFS(Dept,$A27,AttrFlag,1) -> 37 | D27: =IFERROR(C27/B27,0) -> 0.22424242 | E27: =COUNTIFS(Dept,$A27,AttrType,"Voluntary") -> 25 | F27: =COUNTIFS(Dept,$A27,AttrType,"Involuntary") -> 11
A28: Human Resources | B28: =COUNTIFS(Dept,$A28) -> 87 | C28: =COUNTIFS(Dept,$A28,AttrFlag,1) -> 26 | D28: =IFERROR(C28/B28,0) -> 0.29885057 | E28: =COUNTIFS(Dept,$A28,AttrType,"Voluntary") -> 21 | F28: =COUNTIFS(Dept,$A28,AttrType,"Involuntary") -> 4
A29: Operations | B29: =COUNTIFS(Dept,$A29) -> 385 | C29: =COUNTIFS(Dept,$A29,AttrFlag,1) -> 130 | D29: =IFERROR(C29/B29,0) -> 0.33766234 | E29: =COUNTIFS(Dept,$A29,AttrType,"Voluntary") -> 104 | F29: =COUNTIFS(Dept,$A29,AttrType,"Involuntary") -> 25
A30: Total | B30: =SUM(B24:B29) -> 2000 | C30: =SUM(C24:C29) -> 735 | D30: =IFERROR(C30/B30,0) -> 0.3675 | E30: =SUM(E24:E29) -> 557 | F30: =SUM(F24:F29) -> 161 | G30: =IF(B30=TotalEmp,"OK - reconciles","CHECK") -> OK - reconciles
A33: 3. Attrition by Job Role
A34: Segment | B34: Headcount | C34: Leavers | D34: Attrition % | E34: Voluntary | F34: Involuntary
A35: Associate | B35: =COUNTIFS(JobRole,$A35) -> 572 | C35: =COUNTIFS(JobRole,$A35,AttrFlag,1) -> 245 | D35: =IFERROR(C35/B35,0) -> 0.42832168 | E35: =COUNTIFS(JobRole,$A35,AttrType,"Voluntary") -> 184 | F35: =COUNTIFS(JobRole,$A35,AttrType,"Involuntary") -> 53
A36: Analyst | B36: =COUNTIFS(JobRole,$A36) -> 495 | C36: =COUNTIFS(JobRole,$A36,AttrFlag,1) -> 176 | D36: =IFERROR(C36/B36,0) -> 0.35555556 | E36: =COUNTIFS(JobRole,$A36,AttrType,"Voluntary") -> 132 | F36: =COUNTIFS(JobRole,$A36,AttrType,"Involuntary") -> 42
A37: Senior Analyst | B37: =COUNTIFS(JobRole,$A37) -> 312 | C37: =COUNTIFS(JobRole,$A37,AttrFlag,1) -> 106 | D37: =IFERROR(C37/B37,0) -> 0.33974359 | E37: =COUNTIFS(JobRole,$A37,AttrType,"Voluntary") -> 79 | F37: =COUNTIFS(JobRole,$A37,AttrType,"Involuntary") -> 25
A38: Specialist | B38: =COUNTIFS(JobRole,$A38) -> 267 | C38: =COUNTIFS(JobRole,$A38,AttrFlag,1) -> 106 | D38: =IFERROR(C38/B38,0) -> 0.39700375 | E38: =COUNTIFS(JobRole,$A38,AttrType,"Voluntary") -> 84 | F38: =COUNTIFS(JobRole,$A38,AttrType,"Involuntary") -> 18
A39: Team Lead | B39: =COUNTIFS(JobRole,$A39) -> 205 | C39: =COUNTIFS(JobRole,$A39,AttrFlag,1) -> 67 | D39: =IFERROR(C39/B39,0) -> 0.32682927 | E39: =COUNTIFS(JobRole,$A39,AttrType,"Voluntary") -> 55 | F39: =COUNTIFS(JobRole,$A39,AttrType,"Involuntary") -> 12
A40: Manager | B40: =COUNTIFS(JobRole,$A40) -> 149 | C40: =COUNTIFS(JobRole,$A40,AttrFlag,1) -> 35 | D40: =IFERROR(C40/B40,0) -> 0.23489933 | E40: =COUNTIFS(JobRole,$A40,AttrType,"Voluntary") -> 23 | F40: =COUNTIFS(JobRole,$A40,AttrType,"Involuntary") -> 11
A41: Total | B41: =SUM(B35:B40) -> 2000 | C41: =SUM(C35:C40) -> 735 | D41: =IFERROR(C41/B41,0) -> 0.3675 | E41: =SUM(E35:E40) -> 557 | F41: =SUM(F35:F40) -> 161 | G41: =IF(B41=TotalEmp,"OK - reconciles","CHECK") -> OK - reconciles
A44: 4. Attrition by Gender
A45: Segment | B45: Headcount | C45: Leavers | D45: Attrition % | E45: Voluntary | F45: Involuntary
A46: Male | B46: =COUNTIFS(Gender,$A46) -> 1067 | C46: =COUNTIFS(Gender,$A46,AttrFlag,1) -> 383 | D46: =IFERROR(C46/B46,0) -> 0.35895033 | E46: =COUNTIFS(Gender,$A46,AttrType,"Voluntary") -> 292 | F46: =COUNTIFS(Gender,$A46,AttrType,"Involuntary") -> 81
A47: Female | B47: =COUNTIFS(Gender,$A47) -> 933 | C47: =COUNTIFS(Gender,$A47,AttrFlag,1) -> 352 | D47: =IFERROR(C47/B47,0) -> 0.3772776 | E47: =COUNTIFS(Gender,$A47,AttrType,"Voluntary") -> 265 | F47: =COUNTIFS(Gender,$A47,AttrType,"Involuntary") -> 80
...

Sheet Pivots
A1: Pivot-style Cross-tabs with Slicer-style Filters
A2: Pick values in the yellow dropdowns - every table below recalculates. (Native PivotTable + slicer steps are at the bottom of this sheet.)
A3: Filter | B3: Selection | C3: Criteria used | E3: Selected segment
A4: Department | B4: All | C4: =IF(B4="All","*",B4) -> * | E4: Headcount | F4: =COUNTIFS(Dept,$C$4,Gender,$C$5,PerfGroup,$C$6,OverTime,$C$7) -> 2000
A5: Gender | B5: All | C5: =IF(B5="All","*",B5) -> * | E5: Leavers | F5: =COUNTIFS(Dept,$C$4,Gender,$C$5,PerfGroup,$C$6,OverTime,$C$7,AttrFlag,1) -> 735
A6: Performance group | B6: All | C6: =IF(B6="All","*",B6) -> * | E6: Attrition % | F6: =IFERROR(F5/F4,0) -> 0.3675
A7: Overtime | B7: All | C7: =IF(B7="All","*",B7) -> *
A10: A. Attrition % - Job Role x Age Group
A11: Job Role | B11: Under 25 | C11: 25-34 | D11: 35-44 | E11: 45-54 | F11: 55+ | G11: All
A12: Associate | B12: =IFERROR(COUNTIFS(JobRole,$A12,AgeBand,B$11,Dept,$C$4,Gender,$C$5,PerfGroup,$C$6,OverTime,$C$7,AttrFlag,1)/COUNTIFS(JobRole,$A12,AgeBand,B$11,Dept,$C$4,Gender,$C$5,PerfGroup,$C$6,OverTime,$C$7),"") -> 0.61290323 | C12: =IFERROR(COUNTIFS(JobRole,$A12,AgeBand,C$11,Dept,$C$4,Gender,$C$5,PerfGroup,$C$6,OverTime,$C$7,AttrFlag,1)/COUNTIFS(JobRole,$A12,AgeBand,C$11,Dept,$C$4,Gender,$C$5,PerfGroup,$C$6,OverTime,$C$7),"") -> 0.50943396 | D12: =IFERROR(COUNTIFS(JobRole,$A12,AgeBand,D$11,Dept,$C$4,Gender,$C$5,PerfGroup,$C$6,OverTime,$C$7,AttrFlag,1)/COUNTIFS(JobRole,$A12,AgeBand,D$11,Dept,$C$4,Gender,$C$5,PerfGroup,$C$6,OverTime,$C$7),"") -> 0.35390947 | E12: =IFERROR(COUNTIFS(JobRole,$A12,AgeBand,E$11,Dept,$C$4,Gender,$C$5,PerfGroup,$C$6,OverTime,$C$7,AttrFlag,1)/COUNTIFS(JobRole,$A12,AgeBand,E$11,Dept,$C$4,Gender,$C$5,PerfGroup,$C$6,OverTime,$C$7),"") -> 0.125 | F12: =IFERROR(COUNTIFS(JobRole,$A12,AgeBand,F$11,Dept,$C$4,Gender,$C$5,PerfGroup,$C$6,OverTime,$C$7,AttrFlag,1)/COUNTIFS(JobRole,$A12,AgeBand,F$11,Dept,$C$4,Gender,$C$5,PerfGroup,$C$6,OverTime,$C$7),"") | G12: =IFERROR(COUNTIFS(JobRole,$A12,Dept,$C$4,Gender,$C$5,PerfGroup,$C$6,OverTime,$C$7,AttrFlag,1)/COUNTIFS(JobRole,$A12,Dept,$C$4,Gender,$C$5,PerfGroup,$C$6,OverTime,$C$7),"") -> 0.42832168
A13: Analyst | B13: =IFERROR(COUNTIFS(JobRole,$A13,AgeBand,B$11,Dept,$C$4,Gender,$C$5,PerfGroup,$C$6,OverTime,$C$7,AttrFlag,1)/COUNTIFS(JobRole,$A13,AgeBand,B$11,Dept,$C$4,Gender,$C$5,PerfGroup,$C$6,OverTime,$C$7),"") -> 0.60869565 | C13: =IFERROR(COUNTIFS(JobRole,$A13,AgeBand,C$11,Dept,$C$4,Gender,$C$5,PerfGroup,$C$6,OverTime,$C$7,AttrFlag,1)/COUNTIFS(JobRole,$A13,AgeBand,C$11,Dept,$C$4,Gender,$C$5,PerfGroup,$C$6,OverTime,$C$7),"") -> 0.37815126 | D13: =IFERROR(COUNTIFS(JobRole,$A13,AgeBand,D$11,Dept,$C$4,Gender,$C$5,PerfGroup,$C$6,OverTime,$C$7,AttrFlag,1)/COUNTIFS(JobRole,$A13,AgeBand,D$11,Dept,$C$4,Gender,$C$5,PerfGroup,$C$6,OverTime,$C$7),"") -> 0.30434783 | E13: =IFERROR(COUNTIFS(JobRole,$A13,AgeBand,E$11,Dept,$C$4,Gender,$C$5,PerfGroup,$C$6,OverTime,$C$7,AttrFlag,1)/COUNTIFS(JobRole,$A13,AgeBand,E$11,Dept,$C$4,Gender,$C$5,PerfGroup,$C$6,OverTime,$C$7),"") -> 0.28 | F13: =IFERROR(COUNTIFS(JobRole,$A13,AgeBand,F$11,Dept,$C$4,Gender,$C$5,PerfGroup,$C$6,OverTime,$C$7,AttrFlag,1)/COUNTIFS(JobRole,$A13,AgeBand,F$11,Dept,$C$4,Gender,$C$5,PerfGroup,$C$6,OverTime,$C$7),"") | G13: =IFERROR(COUNTIFS(JobRole,$A13,Dept,$C$4,Gender,$C$5,PerfGroup,$C$6,OverTime,$C$7,AttrFlag,1)/COUNTIFS(JobRole,$A13,Dept,$C$4,Gender,$C$5,PerfGroup,$C$6,OverTime,$C$7),"") -> 0.35555556
A14: Senior Analyst | B14: =IFERROR(COUNTIFS(JobRole,$A14,AgeBand,B$11,Dept,$C$4,Gender,$C$5,PerfGroup,$C$6,OverTime,$C$7,AttrFlag,1)/COUNTIFS(JobRole,$A14,AgeBand,B$11,Dept,$C$4,Gender,$C$5,PerfGroup,$C$6,OverTime,$C$7),"") -> 0.76923077 | C14: =IFERROR(COUNTIFS(JobRole,$A14,AgeBand,C$11,Dept,$C$4,Gender,$C$5,PerfGroup,$C$6,OverTime,$C$7,AttrFlag,1)/COUNTIFS(JobRole,$A14,AgeBand,C$11,Dept,$C$4,Gender,$C$5,PerfGroup,$C$6,OverTime,$C$7),"") -> 0.40410959 | D14: =IFERROR(COUNTIFS(JobRole,$A14,AgeBand,D$11,Dept,$C$4,Gender,$C$5,PerfGroup,$C$6,OverTime,$C$7,AttrFlag,1)/COUNTIFS(JobRole,$A14,AgeBand,D$11,Dept,$C$4,Gender,$C$5,PerfGroup,$C$6,OverTime,$C$7),"") -> 0.25714286 | E14: =IFERROR(COUNTIFS(JobRole,$A14,AgeBand,E$11,Dept,$C$4,Gender,$C$5,PerfGroup,$C$6,OverTime,$C$7,AttrFlag,1)/COUNTIFS(JobRole,$A14,AgeBand,E$11,Dept,$C$4,Gender,$C$5,PerfGroup,$C$6,OverTime,$C$7),"") -> 0.076923077 | F14: =IFERROR(COUNTIFS(JobRole,$A14,AgeBand,F$11,Dept,$C$4,Gender,$C$5,PerfGroup,$C$6,OverTime,$C$7,AttrFlag,1)/COUNTIFS(JobRole,$A14,AgeBand,F$11,Dept,$C$4,Gender,$C$5,PerfGroup,$C$6,OverTime,$C$7),"") | G14: =IFERROR(COUNTIFS(JobRole,$A14,Dept,$C$4,Gender,$C$5,PerfGroup,$C$6,OverTime,$C$7,AttrFlag,1)/COUNTIFS(JobRole,$A14,Dept,$C$4,Gender,$C$5,PerfGroup,$C$6,OverTime,$C$7),"") -> 0.33974359
A15: Specialist | B15: =IFERROR(COUNTIFS(JobRole,$A15,AgeBand,B$11,Dept,$C$4,Gender,$C$5,PerfGroup,$C$6,OverTime,$C$7,AttrFlag,1)/COUNTIFS(JobRole,$A15,AgeBand,B$11,Dept,$C$4,Gender,$C$5,PerfGroup,$C$6,OverTime,$C$7),"") -> 0.25 | C15: =IFERROR(COUNTIFS(JobRole,$A15,AgeBand,C$11,Dept,$C$4,Gender,$C$5,PerfGroup,$C$6,OverTime,$C$7,AttrFlag,1)/COUNTIFS(JobRole,$A15,AgeBand,C$11,Dept,$C$4,Gender,$C$5,PerfGroup,$C$6,OverTime,$C$7),"") -> 0.44137931 | D15: =IFERROR(COUNTIFS(JobRole,$A15,AgeBand,D$11,Dept,$C$4,Gender,$C$5,PerfGroup,$C$6,OverTime,$C$7,AttrFlag,1)/COUNTIFS(JobRole,$A15,AgeBand,D$11,Dept,$C$4,Gender,$C$5,PerfGroup,$C$6,OverTime,$C$7),"") -> 0.35714286 | E15: =IFERROR(COUNTIFS(JobRole,$A15,AgeBand,E$11,Dept,$C$4,Gender,$C$5,PerfGroup,$C$6,OverTime,$C$7,AttrFlag,1)/COUNTIFS(JobRole,$A15,AgeBand,E$11,Dept,$C$4,Gender,$C$5,PerfGroup,$C$6,OverTime,$C$7),"") -> 0.36363636 | F15: =IFERROR(COUNTIFS(JobRole,$A15,AgeBand,F$11,Dept,$C$4,Gender,$C$5,PerfGroup,$C$6,OverTime,$C$7,AttrFlag,1)/COUNTIFS(JobRole,$A15,AgeBand,F$11,Dept,$C$4,Gender,$C$5,PerfGroup,$C$6,OverTime,$C$7),"") | G15: =IFERROR(COUNTIFS(JobRole,$A15,Dept,$C$4,Gender,$C$5,PerfGroup,$C$6,OverTime,$C$7,AttrFlag,1)/COUNTIFS(JobRole,$A15,Dept,$C$4,Gender,$C$5,PerfGroup,$C$6,OverTime,$C$7),"") -> 0.39700375
A16: Team Lead | B16: =IFERROR(COUNTIFS(JobRole,$A16,AgeBand,B$11,Dept,$C$4,Gender,$C$5,PerfGroup,$C$6,OverTime,$C$7,AttrFlag,1)/COUNTIFS(JobRole,$A16,AgeBand,B$11,Dept,$C$4,Gender,$C$5,PerfGroup,$C$6,OverTime,$C$7),"") -> 0.63636364 | C16: =IFERROR(COUNTIFS(JobRole,$A16,AgeBand,C$11,Dept,$C$4,Gender,$C$5,PerfGroup,$C$6,OverTime,$C$7,AttrFlag,1)/COUNTIFS(JobRole,$A16,AgeBand,C$11,Dept,$C$4,Gender,$C$5,PerfGroup,$C$6,OverTime,$C$7),"") -> 0.44444444 | D16: =IFERROR(COUNTIFS(JobRole,$A16,AgeBand,D$11,Dept,$C$4,Gender,$C$5,PerfGroup,$C$6,OverTime,$C$7,AttrFlag,1)/COUNTIFS(JobRole,$A16,AgeBand,D$11,Dept,$C$4,Gender,$C$5,PerfGroup,$C$6,OverTime,$C$7),"") -> 0.17777778 | E16: =IFERROR(COUNTIFS(JobRole,$A16,AgeBand,E$11,Dept,$C$4,Gender,$C$5,PerfGroup,$C$6,OverTime,$C$7,AttrFlag,1)/COUNTIFS(JobRole,$A16,AgeBand,E$11,Dept,$C$4,Gender,$C$5,PerfGroup,$C$6,OverTime,$C$7),"") -> 0.23076923 | F16: =IFERROR(COUNTIFS(JobRole,$A16,AgeBand,F$11,Dept,$C$4,Gender,$C$5,PerfGroup,$C$6,OverTime,$C$7,AttrFlag,1)/COUNTIFS(JobRole,$A16,AgeBand,F$11,Dept,$C$4,Gender,$C$5,PerfGroup,$C$6,OverTime,$C$7),"") | G16: =IFERROR(COUNTIFS(JobRole,$A16,Dept,$C$4,Gender,$C$5,PerfGroup,$C$6,OverTime,$C$7,AttrFlag,1)/COUNTIFS(JobRole,$A16,Dept,$C$4,Gender,$C$5,PerfGroup,$C$6,OverTime,$C$7),"") -> 0.32682927
A17: Manager | B17: =IFERROR(COUNTIFS(JobRole,$A17,AgeBand,B$11,Dept,$C$4,Gender,$C$5,PerfGroup,$C$6,OverTime,$C$7,AttrFlag,1)/COUNTIFS(JobRole,$A17,AgeBand,B$11,Dept,$C$4,Gender,$C$5,PerfGroup,$C$6,OverTime,$C$7),"") -> 0.4 | C17: =IFERROR(COUNTIFS(JobRole,$A17,AgeBand,C$11,Dept,$C$4,Gender,$C$5,PerfGroup,$C$6,OverTime,$C$7,AttrFlag,1)/COUNTIFS(JobRole,$A17,AgeBand,C$11,Dept,$C$4,Gender,$C$5,PerfGroup,$C$6,OverTime,$C$7),"") -> 0.28787879 | D17: =IFERROR(COUNTIFS(JobRole,$A17,AgeBand,D$11,Dept,$C$4,Gender,$C$5,PerfGroup,$C$6,OverTime,$C$7,AttrFlag,1)/COUNTIFS(JobRole,$A17,AgeBand,D$11,Dept,$C$4,Gender,$C$5,PerfGroup,$C$6,OverTime,$C$7),"") -> 0.1884058 | E17: =IFERROR(COUNTIFS(JobRole,$A17,AgeBand,E$11,Dept,$C$4,Gender,$C$5,PerfGroup,$C$6,OverTime,$C$7,AttrFlag,1)/COUNTIFS(JobRole,$A17,AgeBand,E$11,Dept,$C$4,Gender,$C$5,PerfGroup,$C$6,OverTime,$C$7),"") -> 0.125 | F17: =IFERROR(COUNTIFS(JobRole,$A17,AgeBand,F$11,Dept,$C$4,Gender,$C$5,PerfGroup,$C$6,OverTime,$C$7,AttrFlag,1)/COUNTIFS(JobRole,$A17,AgeBand,F$11,Dept,$C$4,Gender,$C$5,PerfGroup,$C$6,OverTime,$C$7),"") | G17: =IFERROR(COUNTIFS(JobRole,$A17,Dept,$C$4,Gender,$C$5,PerfGroup,$C$6,OverTime,$C$7,AttrFlag,1)/COUNTIFS(JobRole,$A17,Dept,$C$4,Gender,$C$5,PerfGroup,$C$6,OverTime,$C$7),"") -> 0.23489933
A20: B. Leavers (count) - Job Role x Age Group
A21: Job Role | B21: Under 25 | C21: 25-34 | D21: 35-44 | E21: 45-54 | F21: 55+ | G21: All
A22: Associate | B22: =COUNTIFS(JobRole,$A22,AgeBand,B$21,Dept,$C$4,Gender,$C$5,PerfGroup,$C$6,OverTime,$C$7,AttrFlag,1) -> 19 | C22: =COUNTIFS(JobRole,$A22,AgeBand,C$21,Dept,$C$4,Gender,$C$5,PerfGroup,$C$6,OverTime,$C$7,AttrFlag,1) -> 135 | D22: =COUNTIFS(JobRole,$A22,AgeBand,D$21,Dept,$C$4,Gender,$C$5,PerfGroup,$C$6,OverTime,$C$7,AttrFlag,1) -> 86 | E22: =COUNTIFS(JobRole,$A22,AgeBand,E$21,Dept,$C$4,Gender,$C$5,PerfGroup,$C$6,OverTime,$C$7,AttrFlag,1) -> 4 | F22: =COUNTIFS(JobRole,$A22,AgeBand,F$21,Dept,$C$4,Gender,$C$5,PerfGroup,$C$6,OverTime,$C$7,AttrFlag,1) -> 0 | G22: =COUNTIFS(JobRole,$A22,Dept,$C$4,Gender,$C$5,PerfGroup,$C$6,OverTime,$C$7,AttrFlag,1) -> 245
A23: Analyst | B23: =COUNTIFS(JobRole,$A23,AgeBand,B$21,Dept,$C$4,Gender,$C$5,PerfGroup,$C$6,OverTime,$C$7,AttrFlag,1) -> 14 | C23: =COUNTIFS(JobRole,$A23,AgeBand,C$21,Dept,$C$4,Gender,$C$5,PerfGroup,$C$6,OverTime,$C$7,AttrFlag,1) -> 90 | D23: =COUNTIFS(JobRole,$A23,AgeBand,D$21,Dept,$C$4,Gender,$C$5,PerfGroup,$C$6,OverTime,$C$7,AttrFlag,1) -> 63 | E23: =COUNTIFS(JobRole,$A23,AgeBand,E$21,Dept,$C$4,Gender,$C$5,PerfGroup,$C$6,OverTime,$C$7,AttrFlag,1) -> 7 | F23: =COUNTIFS(JobRole,$A23,AgeBand,F$21,Dept,$C$4,Gender,$C$5,PerfGroup,$C$6,OverTime,$C$7,AttrFlag,1) -> 0 | G23: =COUNTIFS(JobRole,$A23,Dept,$C$4,Gender,$C$5,PerfGroup,$C$6,OverTime,$C$7,AttrFlag,1) -> 176
A24: Senior Analyst | B24: =COUNTIFS(JobRole,$A24,AgeBand,B$21,Dept,$C$4,Gender,$C$5,PerfGroup,$C$6,OverTime,$C$7,AttrFlag,1) -> 10 | C24: =COUNTIFS(JobRole,$A24,AgeBand,C$21,Dept,$C$4,Gender,$C$5,PerfGroup,$C$6,OverTime,$C$7,AttrFlag,1) -> 59 | D24: =COUNTIFS(JobRole,$A24,AgeBand,D$21,Dept,$C$4,Gender,$C$5,PerfGroup,$C$6,OverTime,$C$7,AttrFlag,1) -> 36 | E24: =COUNTIFS(JobRole,$A24,AgeBand,E$21,Dept,$C$4,Gender,$C$5,PerfGroup,$C$6,OverTime,$C$7,AttrFlag,1) -> 1 | F24: =COUNTIFS(JobRole,$A24,AgeBand,F$21,Dept,$C$4,Gender,$C$5,PerfGroup,$C$6,OverTime,$C$7,AttrFlag,1) -> 0 | G24: =COUNTIFS(JobRole,$A24,Dept,$C$4,Gender,$C$5,PerfGroup,$C$6,OverTime,$C$7,AttrFlag,1) -> 106
A25: Specialist | B25: =COUNTIFS(JobRole,$A25,AgeBand,B$21,Dept,$C$4,Gender,$C$5,PerfGroup,$C$6,OverTime,$C$7,AttrFlag,1) -> 3 | C25: =COUNTIFS(JobRole,$A25,AgeBand,C$21,Dept,$C$4,Gender,$C$5,PerfGroup,$C$6,OverTime,$C$7,AttrFlag,1) -> 64 | D25: =COUNTIFS(JobRole,$A25,AgeBand,D$21,Dept,$C$4,Gender,$C$5,PerfGroup,$C$6,OverTime,$C$7,AttrFlag,1) -> 35 | E25: =COUNTIFS(JobRole,$A25,AgeBand,E$21,Dept,$C$4,Gender,$C$5,PerfGroup,$C$6,OverTime,$C$7,AttrFlag,1) -> 4 | F25: =COUNTIFS(JobRole,$A25,AgeBand,F$21,Dept,$C$4,Gender,$C$5,PerfGroup,$C$6,OverTime,$C$7,AttrFlag,1) -> 0 | G25: =COUNTIFS(JobRole,$A25,Dept,$C$4,Gender,$C$5,PerfGroup,$C$6,OverTime,$C$7,AttrFlag,1) -> 106
A26: Team Lead | B26: =COUNTIFS(JobRole,$A26,AgeBand,B$21,Dept,$C$4,Gender,$C$5,PerfGroup,$C$6,OverTime,$C$7,AttrFlag,1) -> 7 | C26: =COUNTIFS(JobRole,$A26,AgeBand,C$21,Dept,$C$4,Gender,$C$5,PerfGroup,$C$6,OverTime,$C$7,AttrFlag,1) -> 40 | D26: =COUNTIFS(JobRole,$A26,AgeBand,D$21,Dept,$C$4,Gender,$C$5,PerfGroup,$C$6,OverTime,$C$7,AttrFlag,1) -> 16 | E26: =COUNTIFS(JobRole,$A26,AgeBand,E$21,Dept,$C$4,Gender,$C$5,PerfGroup,$C$6,OverTime,$C$7,AttrFlag,1) -> 3 | F26: =COUNTIFS(JobRole,$A26,AgeBand,F$21,Dept,$C$4,Gender,$C$5,PerfGroup,$C$6,OverTime,$C$7,AttrFlag,1) -> 0 | G26: =COUNTIFS(JobRole,$A26,Dept,$C$4,Gender,$C$5,PerfGroup,$C$6,OverTime,$C$7,AttrFlag,1) -> 67
A27: Manager | B27: =COUNTIFS(JobRole,$A27,AgeBand,B$21,Dept,$C$4,Gender,$C$5,PerfGroup,$C$6,OverTime,$C$7,AttrFlag,1) -> 2 | C27: =COUNTIFS(JobRole,$A27,AgeBand,C$21,Dept,$C$4,Gender,$C$5,PerfGroup,$C$6,OverTime,$C$7,AttrFlag,1) -> 19 | D27: =COUNTIFS(JobRole,$A27,AgeBand,D$21,Dept,$C$4,Gender,$C$5,PerfGroup,$C$6,OverTime,$C$7,AttrFlag,1) -> 13 | E27: =COUNTIFS(JobRole,$A27,AgeBand,E$21,Dept,$C$4,Gender,$C$5,PerfGroup,$C$6,OverTime,$C$7,AttrFlag,1) -> 1 | F27: =COUNTIFS(JobRole,$A27,AgeBand,F$21,Dept,$C$4,Gender,$C$5,PerfGroup,$C$6,OverTime,$C$7,AttrFlag,1) -> 0 | G27: =COUNTIFS(JobRole,$A27,Dept,$C$4,Gender,$C$5,PerfGroup,$C$6,OverTime,$C$7,AttrFlag,1) -> 35
A30: C. Attrition % - Job Role x Gender
A31: Job Role | B31: Male | C31: Female | D31: All
A32: Associate | B32: =IFERROR(COUNTIFS(JobRole,$A32,Gender,B$31,Dept,$C$4,Gender,$C$5,PerfGroup,$C$6,OverTime,$C$7,AttrFlag,1)/COUNTIFS(JobRole,$A32,Gender,B$31,Dept,$C$4,Gender,$C$5,PerfGroup,$C$6,OverTime,$C$7),"") -> 0.39935065 | C32: =IFERROR(COUNTIFS(JobRole,$A32,Gender,C$31,Dept,$C$4,Gender,$C$5,PerfGroup,$C$6,OverTime,$C$7,AttrFlag,1)/COUNTIFS(JobRole,$A32,Gender,C$31,Dept,$C$4,Gender,$C$5,PerfGroup,$C$6,OverTime,$C$7),"") -> 0.46212121 | D32: =IFERROR(COUNTIFS(JobRole,$A32,Dept,$C$4,Gender,$C$5,PerfGroup,$C$6,OverTime,$C$7,AttrFlag,1)/COUNTIFS(JobRole,$A32,Dept,$C$4,Gender,$C$5,PerfGroup,$C$6,OverTime,$C$7),"") -> 0.42832168
A33: Analyst | B33: =IFERROR(COUNTIFS(JobRole,$A33,Gender,B$31,Dept,$C$4,Gender,$C$5,PerfGroup,$C$6,OverTime,$C$7,AttrFlag,1)/COUNTIFS(JobRole,$A33,Gender,B$31,Dept,$C$4,Gender,$C$5,PerfGroup,$C$6,OverTime,$C$7),"") -> 0.35658915 | C33: =IFERROR(COUNTIFS(JobRole,$A33,Gender,C$31,Dept,$C$4,Gender,$C$5,PerfGroup,$C$6,OverTime,$C$7,AttrFlag,1)/COUNTIFS(JobRole,$A33,Gender,C$31,Dept,$C$4,Gender,$C$5,PerfGroup,$C$6,OverTime,$C$7),"") -> 0.35443038 | D33: =IFERROR(COUNTIFS(JobRole,$A33,Dept,$C$4,Gender,$C$5,PerfGroup,$C$6,OverTime,$C$7,AttrFlag,1)/COUNTIFS(JobRole,$A33,Dept,$C$4,Gender,$C$5,PerfGroup,$C$6,OverTime,$C$7),"") -> 0.35555556
A34: Senior Analyst | B34: =IFERROR(COUNTIFS(JobRole,$A34,Gender,B$31,Dept,$C$4,Gender,$C$5,PerfGroup,$C$6,OverTime,$C$7,AttrFlag,1)/COUNTIFS(JobRole,$A34,Gender,B$31,Dept,$C$4,Gender,$C$5,PerfGroup,$C$6,OverTime,$C$7),"") -> 0.31875 | C34: =IFERROR(COUNTIFS(JobRole,$A34,Gender,C$31,Dept,$C$4,Gender,$C$5,PerfGroup,$C$6,OverTime,$C$7,AttrFlag,1)/COUNTIFS(JobRole,$A34,Gender,C$31,Dept,$C$4,Gender,$C$5,PerfGroup,$C$6,OverTime,$C$7),"") -> 0.36184211 | D34: =IFERROR(COUNTIFS(JobRole,$A34,Dept,$C$4,Gender,$C$5,PerfGroup,$C$6,OverTime,$C$7,AttrFlag,1)/COUNTIFS(JobRole,$A34,Dept,$C$4,Gender,$C$5,PerfGroup,$C$6,OverTime,$C$7),"") -> 0.33974359
A35: Specialist | B35: =IFERROR(COUNTIFS(JobRole,$A35,Gender,B$31,Dept,$C$4,Gender,$C$5,PerfGroup,$C$6,OverTime,$C$7,AttrFlag,1)/COUNTIFS(JobRole,$A35,Gender,B$31,Dept,$C$4,Gender,$C$5,PerfGroup,$C$6,OverTime,$C$7),"") -> 0.40277778 | C35: =IFERROR(COUNTIFS(JobRole,$A35,Gender,C$31,Dept,$C$4,Gender,$C$5,PerfGroup,$C$6,OverTime,$C$7,AttrFlag,1)/COUNTIFS(JobRole,$A35,Gender,C$31,Dept,$C$4,Gender,$C$5,PerfGroup,$C$6,OverTime,$C$7),"") -> 0.3902439 | D35: =IFERROR(COUNTIFS(JobRole,$A35,Dept,$C$4,Gender,$C$5,PerfGroup,$C$6,OverTime,$C$7,AttrFlag,1)/COUNTIFS(JobRole,$A35,Dept,$C$4,Gender,$C$5,PerfGroup,$C$6,OverTime,$C$7),"") -> 0.39700375
A36: Team Lead | B36: =IFERROR(COUNTIFS(JobRole,$A36,Gender,B$31,Dept,$C$4,Gender,$C$5,PerfGroup,$C$6,OverTime,$C$7,AttrFlag,1)/COUNTIFS(JobRole,$A36,Gender,B$31,Dept,$C$4,Gender,$C$5,PerfGroup,$C$6,OverTime,$C$7),"") -> 0.34513274 | C36: =IFERROR(COUNTIFS(JobRole,$A36,Gender,C$31,Dept,$C$4,Gender,$C$5,PerfGroup,$C$6,OverTime,$C$7,AttrFlag,1)/COUNTIFS(JobRole,$A36,Gender,C$31,Dept,$C$4,Gender,$C$5,PerfGroup,$C$6,OverTime,$C$7),"") -> 0.30434783 | D36: =IFERROR(COUNTIFS(JobRole,$A36,Dept,$C$4,Gender,$C$5,PerfGroup,$C$6,OverTime,$C$7,AttrFlag,1)/COUNTIFS(JobRole,$A36,Dept,$C$4,Gender,$C$5,PerfGroup,$C$6,OverTime,$C$7),"") -> 0.32682927
A37: Manager | B37: =IFERROR(COUNTIFS(JobRole,$A37,Gender,B$31,Dept,$C$4,Gender,$C$5,PerfGroup,$C$6,OverTime,$C$7,AttrFlag,1)/COUNTIFS(JobRole,$A37,Gender,B$31,Dept,$C$4,Gender,$C$5,PerfGroup,$C$6,OverTime,$C$7),"") -> 0.23809524 | C37: =IFERROR(COUNTIFS(JobRole,$A37,Gender,C$31,Dept,$C$4,Gender,$C$5,PerfGroup,$C$6,OverTime,$C$7,AttrFlag,1)/COUNTIFS(JobRole,$A37,Gender,C$31,Dept,$C$4,Gender,$C$5,PerfGroup,$C$6,OverTime,$C$7),"") -> 0.23076923 | D37: =IFERROR(COUNTIFS(JobRole,$A37,Dept,$C$4,Gender,$C$5,PerfGroup,$C$6,OverTime,$C$7,AttrFlag,1)/COUNTIFS(JobRole,$A37,Dept,$C$4,Gender,$C$5,PerfGroup,$C$6,OverTime,$C$7),"") -> 0.23489933
A40: D. Attrition % - Job Role x Tenure Band
A41: Job Role | B41: 0-1 yrs | C41: 1-3 yrs | D41: 3-5 yrs | E41: 5-10 yrs | F41: 10+ yrs | G41: All
A42: Associate | B42: =IFERROR(COUNTIFS(JobRole,$A42,TenureBand,B$41,Dept,$C$4,Gender,$C$5,PerfGroup,$C$6,OverTime,$C$7,AttrFlag,1)/COUNTIFS(JobRole,$A42,TenureBand,B$41,Dept,$C$4,Gender,$C$5,PerfGroup,$C$6,OverTime,$C$7),"") -> 0.60869565 | C42: =IFERROR(COUNTIFS(JobRole,$A42,TenureBand,C$41,Dept,$C$4,Gender,$C$5,PerfGroup,$C$6,OverTime,$C$7,AttrFlag,1)/COUNTIFS(JobRole,$A42,TenureBand,C$41,Dept,$C$4,Gender,$C$5,PerfGroup,$C$6,OverTime,$C$7),"") -> 0.52631579 | D42: =IFERROR(COUNTIFS(JobRole,$A42,TenureBand,D$41,Dept,$C$4,Gender,$C$5,PerfGroup,$C$6,OverTime,$C$7,AttrFlag,1)/COUNTIFS(JobRole,$A42,TenureBand,D$41,Dept,$C$4,Gender,$C$5,PerfGroup,$C$6,OverTime,$C$7),"") -> 0.51898734 | E42: =IFERROR(COUNTIFS(JobRole,$A42,TenureBand,E$41,Dept,$C$4,Gender,$C$5,PerfGroup,$C$6,OverTime,$C$7,AttrFlag,1)/COUNTIFS(JobRole,$A42,TenureBand,E$41,Dept,$C$4,Gender,$C$5,PerfGroup,$C$6,OverTime,$C$7),"") -> 0.35465116 | F42: =IFERROR(COUNTIFS(JobRole,$A42,TenureBand,F$41,Dept,$C$4,Gender,$C$5,PerfGroup,$C$6,OverTime,$C$7,AttrFlag,1)/COUNTIFS(JobRole,$A42,TenureBand,F$41,Dept,$C$4,Gender,$C$5,PerfGroup,$C$6,OverTime,$C$7),"") -> 0.17708333 | G42: =IFERROR(COUNTIFS(JobRole,$A42,Dept,$C$4,Gender,$C$5,PerfGroup,$C$6,OverTime,$C$7,AttrFlag,1)/COUNTIFS(JobRole,$A42,Dept,$C$4,Gender,$C$5,PerfGroup,$C$6,OverTime,$C$7),"") -> 0.42832168
A43: Analyst | B43: =IFERROR(COUNTIFS(JobRole,$A43,TenureBand,B$41,Dept,$C$4,Gender,$C$5,PerfGroup,$C$6,OverTime,$C$7,AttrFlag,1)/COUNTIFS(JobRole,$A43,TenureBand,B$41,Dept,$C$4,Gender,$C$5,PerfGroup,$C$6,OverTime,$C$7),"") -> 0.48648649 | C43: =IFERROR(COUNTIFS(JobRole,$A43,TenureBand,C$41,Dept,$C$4,Gender,$C$5,PerfGroup,$C$6,OverTime,$C$7,AttrFlag,1)/COUNTIFS(JobRole,$A43,TenureBand,C$41,Dept,$C$4,Gender,$C$5,PerfGroup,$C$6,OverTime,$C$7),"") -> 0.456 | D43: =IFERROR(COUNTIFS(JobRole,$A43,TenureBand,D$41,Dept,$C$4,Gender,$C$5,PerfGroup,$C$6,OverTime,$C$7,AttrFlag,1)/COUNTIFS(JobRole,$A43,TenureBand,D$41,Dept,$C$4,Gender,$C$5,PerfGroup,$C$6,OverTime,$C$7),"") -> 0.31428571 | E43: =IFERROR(COUNTIFS(JobRole,$A43,TenureBand,E$41,Dept,$C$4,Gender,$C$5,PerfGroup,$C$6,OverTime,$C$7,AttrFlag,1)/COUNTIFS(JobRole,$A43,TenureBand,E$41,Dept,$C$4,Gender,$C$5,PerfGroup,$C$6,OverTime,$C$7),"") -> 0.34507042 | F43: =IFERROR(COUNTIFS(JobRole,$A43,TenureBand,F$41,Dept,$C$4,Gender,$C$5,PerfGroup,$C$6,OverTime,$C$7,AttrFlag,1)/COUNTIFS(JobRole,$A43,TenureBand,F$41,Dept,$C$4,Gender,$C$5,PerfGroup,$C$6,OverTime,$C$7),"") -> 0.14285714 | G43: =IFERROR(COUNTIFS(JobRole,$A43,Dept,$C$4,Gender,$C$5,PerfGroup,$C$6,OverTime,$C$7,AttrFlag,1)/COUNTIFS(JobRole,$A43,Dept,$C$4,Gender,$C$5,PerfGroup,$C$6,OverTime,$C$7),"") -> 0.35555556
A44: Senior Analyst | B44: =IFERROR(COUNTIFS(JobRole,$A44,TenureBand,B$41,Dept,$C$4,Gender,$C$5,PerfGroup,$C$6,OverTime,$C$7,AttrFlag,1)/COUNTIFS(JobRole,$A44,TenureBand,B$41,Dept,$C$4,Gender,$C$5,PerfGroup,$C$6,OverTime,$C$7),"") -> 0.5625 | C44: =IFERROR(COUNTIFS(JobRole,$A44,TenureBand,C$41,Dept,$C$4,Gender,$C$5,PerfGroup,$C$6,OverTime,$C$7,AttrFlag,1)/COUNTIFS(JobRole,$A44,TenureBand,C$41,Dept,$C$4,Gender,$C$5,PerfGroup,$C$6,OverTime,$C$7),"") -> 0.41269841 | D44: =IFERROR(COUNTIFS(JobRole,$A44,TenureBand,D$41,Dept,$C$4,Gender,$C$5,PerfGroup,$C$6,OverTime,$C$7,AttrFlag,1)/COUNTIFS(JobRole,$A44,TenureBand,D$41,Dept,$C$4,Gender,$C$5,PerfGroup,$C$6,OverTime,$C$7),"") -> 0.34782609 | E44: =IFERROR(COUNTIFS(JobRole,$A44,TenureBand,E$41,Dept,$C$4,Gender,$C$5,PerfGroup,$C$6,OverTime,$C$7,AttrFlag,1)/COUNTIFS(JobRole,$A44,TenureBand,E$41,Dept,$C$4,Gender,$C$5,PerfGroup,$C$6,OverTime,$C$7),"") -> 0.28301887 | F44: =IFERROR(COUNTIFS(JobRole,$A44,TenureBand,F$41,Dept,$C$4,Gender,$C$5,PerfGroup,$C$6,OverTime,$C$7,AttrFlag,1)/COUNTIFS(JobRole,$A44,TenureBand,F$41,Dept,$C$4,Gender,$C$5,PerfGroup,$C$6,OverTime,$C$7),"") -> 0.14285714 | G44: =IFERROR(COUNTIFS(JobRole,$A44,Dept,$C$4,Gender,$C$5,PerfGroup,$C$6,OverTime,$C$7,AttrFlag,1)/COUNTIFS(JobRole,$A44,Dept,$C$4,Gender,$C$5,PerfGroup,$C$6,OverTime,$C$7),"") -> 0.33974359
A45: Specialist | B45: =IFERROR(COUNTIFS(JobRole,$A45,TenureBand,B$41,Dept,$C$4,Gender,$C$5,PerfGroup,$C$6,OverTime,$C$7,AttrFlag,1)/COUNTIFS(JobRole,$A45,TenureBand,B$41,Dept,$C$4,Gender,$C$5,PerfGroup,$C$6,OverTime,$C$7),"") -> 0.47058824 | C45: =IFERROR(COUNTIFS(JobRole,$A45,TenureBand,C$41,Dept,$C$4,Gender,$C$5,PerfGroup,$C$6,OverTime,$C$7,AttrFlag,1)/COUNTIFS(JobRole,$A45,TenureBand,C$41,Dept,$C$4,Gender,$C$5,PerfGroup,$C$6,OverTime,$C$7),"") -> 0.46969697 | D45: =IFERROR(COUNTIFS(JobRole,$A45,TenureBand,D$41,Dept,$C$4,Gender,$C$5,PerfGroup,$C$6,OverTime,$C$7,AttrFlag,1)/COUNTIFS(JobRole,$A45,TenureBand,D$41,Dept,$C$4,Gender,$C$5,PerfGroup,$C$6,OverTime,$C$7),"") -> 0.51351351 | E45: =IFERROR(COUNTIFS(JobRole,$A45,TenureBand,E$41,Dept,$C$4,Gender,$C$5,PerfGroup,$C$6,OverTime,$C$7,AttrFlag,1)/COUNTIFS(JobRole,$A45,TenureBand,E$41,Dept,$C$4,Gender,$C$5,PerfGroup,$C$6,OverTime,$C$7),"") -> 0.35616438 | F45: =IFERROR(COUNTIFS(JobRole,$A45,TenureBand,F$41,Dept,$C$4,Gender,$C$5,PerfGroup,$C$6,OverTime,$C$7,AttrFlag,1)/COUNTIFS(JobRole,$A45,TenureBand,F$41,Dept,$C$4,Gender,$C$5,PerfGroup,$C$6,OverTime,$C$7),"") -> 0.15 | G45: =IFERROR(COUNTIFS(JobRole,$A45,Dept,$C$4,Gender,$C$5,PerfGroup,$C$6,OverTime,$C$7,AttrFlag,1)/COUNTIFS(JobRole,$A45,Dept,$C$4,Gender,$C$5,PerfGroup,$C$6,OverTime,$C$7),"") -> 0.39700375
A46: Team Lead | B46: =IFERROR(COUNTIFS(JobRole,$A46,TenureBand,B$41,Dept,$C$4,Gender,$C$5,PerfGroup,$C$6,OverTime,$C$7,AttrFlag,1)/COUNTIFS(JobRole,$A46,TenureBand,B$41,Dept,$C$4,Gender,$C$5,PerfGroup,$C$6,OverTime,$C$7),"") -> 0.39130435 | C46: =IFERROR(COUNTIFS(JobRole,$A46,TenureBand,C$41,Dept,$C$4,Gender,$C$5,PerfGroup,$C$6,OverTime,$C$7,AttrFlag,1)/COUNTIFS(JobRole,$A46,TenureBand,C$41,Dept,$C$4,Gender,$C$5,PerfGroup,$C$6,OverTime,$C$7),"") -> 0.47916667 | D46: =IFERROR(COUNTIFS(JobRole,$A46,TenureBand,D$41,Dept,$C$4,Gender,$C$5,PerfGroup,$C$6,OverTime,$C$7,AttrFlag,1)/COUNTIFS(JobRole,$A46,TenureBand,D$41,Dept,$C$4,Gender,$C$5,PerfGroup,$C$6,OverTime,$C$7),"") -> 0.35294118 | E46: =IFERROR(COUNTIFS(JobRole,$A46,TenureBand,E$41,Dept,$C$4,Gender,$C$5,PerfGroup,$C$6,OverTime,$C$7,AttrFlag,1)/COUNTIFS(JobRole,$A46,TenureBand,E$41,Dept,$C$4,Gender,$C$5,PerfGroup,$C$6,OverTime,$C$7),"") -> 0.28571429 | F46: =IFERROR(COUNTIFS(JobRole,$A46,TenureBand,F$41,Dept,$C$4,Gender,$C$5,PerfGroup,$C$6,OverTime,$C$7,AttrFlag,1)/COUNTIFS(JobRole,$A46,TenureBand,F$41,Dept,$C$4,Gender,$C$5,PerfGroup,$C$6,OverTime,$C$7),"") -> 0.13513514 | G46: =IFERROR(COUNTIFS(JobRole,$A46,Dept,$C$4,Gender,$C$5,PerfGroup,$C$6,OverTime,$C$7,AttrFlag,1)/COUNTIFS(JobRole,$A46,Dept,$C$4,Gender,$C$5,PerfGroup,$C$6,OverTime,$C$7),"") -> 0.32682927
A47: Manager | B47: =IFERROR(COUNTIFS(JobRole,$A47,TenureBand,B$41,Dept,$C$4,Gender,$C$5,PerfGroup,$C$6,OverTime,$C$7,AttrFlag,1)/COUNTIFS(JobRole,$A47,TenureBand,B$41,Dept,$C$4,Gender,$C$5,PerfGroup,$C$6,OverTime,$C$7),"") -> 0.52941176 | C47: =IFERROR(COUNTIFS(JobRole,$A47,TenureBand,C$41,Dept,$C$4,Gender,$C$5,PerfGroup,$C$6,OverTime,$C$7,AttrFlag,1)/COUNTIFS(JobRole,$A47,TenureBand,C$41,Dept,$C$4,Gender,$C$5,PerfGroup,$C$6,OverTime,$C$7),"") -> 0.35714286 | D47: =IFERROR(COUNTIFS(JobRole,$A47,TenureBand,D$41,Dept,$C$4,Gender,$C$5,PerfGroup,$C$6,OverTime,$C$7,AttrFlag,1)/COUNTIFS(JobRole,$A47,TenureBand,D$41,Dept,$C$4,Gender,$C$5,PerfGroup,$C$6,OverTime,$C$7),"") -> 0.20689655 | E47: =IFERROR(COUNTIFS(JobRole,$A47,TenureBand,E$41,Dept,$C$4,Gender,$C$5,PerfGroup,$C$6,OverTime,$C$7,AttrFlag,1)/COUNTIFS(JobRole,$A47,TenureBand,E$41,Dept,$C$4,Gender,$C$5,PerfGroup,$C$6,OverTime,$C$7),"") -> 0.18421053 | F47: =IFERROR(COUNTIFS(JobRole,$A47,TenureBand,F$41,Dept,$C$4,Gender,$C$5,PerfGroup,$C$6,OverTime,$C$7,AttrFlag,1)/COUNTIFS(JobRole,$A47,TenureBand,F$41,Dept,$C$4,Gender,$C$5,PerfGroup,$C$6,OverTime,$C$7),"") -> 0.081081081 | G47: =IFERROR(COUNTIFS(JobRole,$A47,Dept,$C$4,Gender,$C$5,PerfGroup,$C$6,OverTime,$C$7,AttrFlag,1)/COUNTIFS(JobRole,$A47,Dept,$C$4,Gender,$C$5,PerfGroup,$C$6,OverTime,$C$7),"") -> 0.23489933
A50: How to add a native PivotTable + slicers (2 minutes, in desktop Excel)
...

Sheet Dashboard
B1: Employee Attrition Dashboard
B2: Window: Jan-2022 to Dec-2025 | Source: Clean_Data via Analysis tab | Rates are leavers / employees unless labelled annual
B4: Total employees | D4: Active employees | F4: Leavers | H4: Cumulative attrition % | K4: Avg annual attrition | M4: Voluntary share | O4: Avg tenure of leavers (yrs) | Q4: Est. annual replacement cost (INR mn)
B5: =Analysis!$B$5 -> 2000 | D5: =Analysis!$B$6 -> 1265 | F5: =Analysis!$B$7 -> 735 | H5: =Analysis!$B$8 -> 0.3675 | K5: =Analysis!$B$12 -> 0.14617617 | M5: =Analysis!$B$11 -> 0.75782313 | O5: =Analysis!$B$13 -> 3.9238231 | Q5: =Analysis!$B$18/1000000 -> 90.03525
B105: Heatmap: attrition % by Job Role x Department (red = higher risk)
B106: Job Role | D106: =Analysis!B194 -> Sales | E106: =Analysis!C194 -> Engineering | F106: =Analysis!D194 -> Customer Support | G106: =Analysis!E194 -> Finance | H106: =Analysis!F194 -> Human Resources | I106: =Analysis!G194 -> Operations
